Workbook

Sheet Foglio1
A1: Date | B1: Ricavo
A2: 44872 | B2: 1735.65
A3: 44873 | B3: 3105.1125
A4: 44874 | B4: 2845.14
A5: 44875 | B5: 3305.6775
A6: 44876 | B6: 2884.926
A7: 44877 | B7: 2804.388
A8: 44878 | B8: 7792.5714
A9: 44879 | B9: 5424.4833
A10: 44880 | B10: 2725.632
A11: 44881 | B11: 2725.632
A12: 44882 | B12: 2804.388
A13: 44883 | B13: 2883.144
... A54: 44924 | B54: 4203.91

Sheet Foglio2
A3: Etichette di riga | B3: Somma di Quantity2
A4: Beverages | B4: 35666
A5: Fries | B5: 32067
A6: Burgers | B6: 29572
A7: Chicken Sandwiches | B7: 11184
A8: Sides & Other | B8: 10050
A9: Totale complessivo | B9: 118539
A13: Etichette di riga | B13: Somma di Ricavo
A14: Joao Silva | B14: 283555.36
A15: Pablo Perez | B15: 136430.04
A16: Remy Monet | B16: 79927.9
A17: Tom Jackson | B17: 211522.88
A18: Walter Muller | B18: 100698.95
A19: Totale complessivo | B19: 812135.13
A29: Etichette di riga | B29: Somma di Ricavo
A30: nov | B30: 75073.205
A31: dic | B31: 91138.285
A32: Totale complessivo | B32: 166211.49
A42: Etichette di riga | B42: Somma di Ricavo
A43: #VALUE! | B43: 0.098416996
A44: #VALUE! | B44: 0.12399285
A45: #VALUE! | B45: 0.26045281
A46: #VALUE! | B46: 0.349148
A47: #VALUE! | B47: 0.16798933
A48: Totale complessivo | B48: 1
A57: Somma di Quantity2 | B57: Etichette di colonna
A58: Etichette di riga | B58: Remy Monet | C58: Totale complessivo
A59: Beverages | B59: 3526 | C59: 3526
A60: Burgers | B60: 3036 | C60: 3036
A61: Chicken Sandwiches | B61: 1212 | C61: 1212
A62: Fries | B62: 3729 | C62: 3729
A63: Sides & Other | B63: 1005 | C63: 1005
A64: Totale complessivo | B64: 12508 | C64: 12508
A71: Etichette di riga | B71: Somma di Ricavo
A72: 10483 | B72: 0.39498042
A73: 10485 | B73: 0.34586021
A74: 10482 | B74: 0.25915936
A75: Totale complessivo | B75: 1
A85: City | B85: #VALUE!
A87: Etichette di riga | B87: Somma di Ricavo
...

Sheet Raw
B2: Order ID | C2: Date | D2: Product | E2: Price | F2: Purchase Type | G2: Payment Method | H2: Manager2 | I2: Quantity | J2: City | K2: Paese/area geografica | L2: Ricavo
B3: 10452 | C3: 44872 | D3: Fries | E3: 3.49 | F3: Online | G3: Gift Card | H3: Tom Jackson | I3: 574 | J3: #VALUE! | K3: {=_FV(Tabella2[[#This Row],[City]],"Paese/area geografica",TRUE)} -> #VALUE! | L3: =Tabella2[[#This Row],[Quantity]]*Tabella2[[#This Row],[Price]] -> 2003.26 | O3: Prezzo
B4: 10453 | C4: 44872 | D4: Beverages | E4: 2.95 | F4: Online | G4: Gift Card | H4: Pablo Perez | I4: 746 | J4: #VALUE! | K4: {=_FV(Tabella2[[#This Row],[City]],"Paese/area geografica",TRUE)} -> #VALUE! | L4: =Tabella2[[#This Row],[Quantity]]*Tabella2[[#This Row],[Price]] -> 2200.7
B5: 10454 | C5: 44872 | D5: Sides & Other | E5: 4.99 | F5: In-store | G5: Gift Card | H5: Joao Silva | I5: 201 | J5: #VALUE! | K5: {=_FV(Tabella2[[#This Row],[City]],"Paese/area geografica",TRUE)} -> #VALUE! | L5: =Tabella2[[#This Row],[Quantity]]*Tabella2[[#This Row],[Price]] -> 1002.99 | O5: Media | P5: 7.3410117
B6: 10455 | C6: 44873 | D6: Burgers | E6: 12.99 | F6: In-store | G6: Credit Card | H6: Walter Muller | I6: 570 | J6: #VALUE! | K6: {=_FV(Tabella2[[#This Row],[City]],"Paese/area geografica",TRUE)} -> #VALUE! | L6: =Tabella2[[#This Row],[Quantity]]*Tabella2[[#This Row],[Price]] -> 7404.3 | O6: Errore standard | P6: 0.30396506
B7: 10456 | C7: 44873 | D7: Chicken Sandwiches | E7: 9.95 | F7: In-store | G7: Credit Card | H7: Walter Muller | I7: 202 | J7: #VALUE! | K7: {=_FV(Tabella2[[#This Row],[City]],"Paese/area geografica",TRUE)} -> #VALUE! | L7: =Tabella2[[#This Row],[Quantity]]*Tabella2[[#This Row],[Price]] -> 2009.9 | O7: Mediana | P7: 4.99
B8: 10457 | C8: 44873 | D8: Fries | E8: 3.49 | F8: In-store | G8: Credit Card | H8: Remy Monet | I8: 574 | J8: #VALUE! | K8: {=_FV(Tabella2[[#This Row],[City]],"Paese/area geografica",TRUE)} -> #VALUE! | L8: =Tabella2[[#This Row],[Quantity]]*Tabella2[[#This Row],[Price]] -> 2003.26 | O8: Moda | P8: 12.99
B9: 10459 | C9: 44873 | D9: Sides & Other | E9: 4.99 | F9: In-store | G9: Credit Card | H9: Walter Muller | I9: 201 | J9: #VALUE! | K9: {=_FV(Tabella2[[#This Row],[City]],"Paese/area geografica",TRUE)} -> #VALUE! | L9: =Tabella2[[#This Row],[Quantity]]*Tabella2[[#This Row],[Price]] -> 1002.99 | O9: Deviazione standard | P9: 4.8729306
B10: 10460 | C10: 44874 | D10: Burgers | E10: 12.99 | F10: In-store | G10: Credit Card | H10: Remy Monet | I10: 555 | J10: #VALUE! | K10: {=_FV(Tabella2[[#This Row],[City]],"Paese/area geografica",TRUE)} -> #VALUE! | L10: =Tabella2[[#This Row],[Quantity]]*Tabella2[[#This Row],[Price]] -> 7209.45 | O10: Varianza campionaria | P10: 23.745453
B11: 10461 | C11: 44874 | D11: Chicken Sandwiches | E11: 9.95 | F11: In-store | G11: Credit Card | H11: Remy Monet | I11: 202 | J11: #VALUE! | K11: {=_FV(Tabella2[[#This Row],[City]],"Paese/area geografica",TRUE)} -> #VALUE! | L11: =Tabella2[[#This Row],[Quantity]]*Tabella2[[#This Row],[Price]] -> 2009.9 | O11: Curtosi | P11: 4.6742476
B12: 10462 | C12: 44874 | D12: Fries | E12: 3.49 | F12: In-store | G12: Credit Card | H12: Remy Monet | I12: 574 | J12: #VALUE! | K12: {=_FV(Tabella2[[#This Row],[City]],"Paese/area geografica",TRUE)} -> #VALUE! | L12: =Tabella2[[#This Row],[Quantity]]*Tabella2[[#This Row],[Price]] -> 2003.26 | O12: Asimmetria | P12: 1.6233289
B13: 10463 | C13: 44874 | D13: Beverages | E13: 2.95 | F13: In-store | G13: Credit Card | H13: Remy Monet | I13: 678 | J13: #VALUE! | K13: {=_FV(Tabella2[[#This Row],[City]],"Paese/area geografica",TRUE)} -> #VALUE! | L13: =Tabella2[[#This Row],[Quantity]]*Tabella2[[#This Row],[Price]] -> 2000.1 | O13: Intervallo | P13: 30.27
B14: 10464 | C14: 44874 | D14: Sides & Other | E14: 4.99 | F14: In-store | G14: Credit Card | H14: Remy Monet | I14: 201 | J14: #VALUE! | K14: {=_FV(Tabella2[[#This Row],[City]],"Paese/area geografica",TRUE)} -> #VALUE! | L14: =Tabella2[[#This Row],[Quantity]]*Tabella2[[#This Row],[Price]] -> 1002.99 | O14: Minimo | P14: 2.95
B15: 10465 | C15: 44875 | D15: Burgers | E15: 12.99 | F15: In-store | G15: Credit Card | H15: Pablo Perez | I15: 555 | J15: #VALUE! | K15: {=_FV(Tabella2[[#This Row],[City]],"Paese/area geografica",TRUE)} -> #VALUE! | L15: =Tabella2[[#This Row],[Quantity]]*Tabella2[[#This Row],[Price]] -> 7209.45 | O15: Massimo | P15: 33.22
B16: 10466 | C16: 44875 | D16: Chicken Sandwiches | E16: 9.95 | F16: In-store | G16: Credit Card | H16: Pablo Perez | I16: 202 | J16: #VALUE! | K16: {=_FV(Tabella2[[#This Row],[City]],"Paese/area geografica",TRUE)} -> #VALUE! | L16: =Tabella2[[#This Row],[Quantity]]*Tabella2[[#This Row],[Price]] -> 2009.9 | O16: Somma | P16: 1886.64
B17: 10467 | C17: 44875 | D17: Fries | E17: 3.49 | F17: In-store | G17: Credit Card | H17: Pablo Perez | I17: 574 | J17: #VALUE! | K17: {=_FV(Tabella2[[#This Row],[City]],"Paese/area geografica",TRUE)} -> #VALUE! | L17: =Tabella2[[#This Row],[Quantity]]*Tabella2[[#This Row],[Price]] -> 2003.26 | O17: Conteggio | P17: 257
B18: 10468 | C18: 44875 | D18: Beverages | E18: 2.95 | F18: In-store | G18: Credit Card | H18: Pablo Perez | I18: 678 | J18: #VALUE! | K18: {=_FV(Tabella2[[#This Row],[City]],"Paese/area geografica",TRUE)} -> #VALUE! | L18: =Tabella2[[#This Row],[Quantity]]*Tabella2[[#This Row],[Price]] -> 2000.1
B19: 10470 | C19: 44876 | D19: Burgers | E19: 12.99 | F19: In-store | G19: Credit Card | H19: Pablo Perez | I19: 555 | J19: #VALUE! | K19: {=_FV(Tabella2[[#This Row],[City]],"Paese/area geografica",TRUE)} -> #VALUE! | L19: =Tabella2[[#This Row],[Quantity]]*Tabella2[[#This Row],[Price]] -> 7209.45
B20: 10471 | C20: 44876 | D20: Chicken Sandwiches | E20: 9.95 | F20: In-store | G20: Credit Card | H20: Pablo Perez | I20: 202 | J20: #VALUE! | K20: {=_FV(Tabella2[[#This Row],[City]],"Paese/area geografica",TRUE)} -> #VALUE! | L20: =Tabella2[[#This Row],[Quantity]]*Tabella2[[#This Row],[Price]] -> 2009.9 | O20: Quantità
B21: 10472 | C21: 44876 | D21: Fries | E21: 3.49 | F21: In-store | G21: Credit Card | H21: Pablo Perez | I21: 631 | J21: #VALUE! | K21: {=_FV(Tabella2[[#This Row],[City]],"Paese/area geografica",TRUE)} -> #VALUE! | L21: =Tabella2[[#This Row],[Quantity]]*Tabella2[[#This Row],[Price]] -> 2202.19
B22: 10473 | C22: 44876 | D22: Beverages | E22: 2.95 | F22: In-store | G22: Credit Card | H22: Pablo Perez | I22: 678 | J22: #VALUE! | K22: {=_FV(Tabella2[[#This Row],[City]],"Paese/area geografica",TRUE)} -> #VALUE! | L22: =Tabella2[[#This Row],[Quantity]]*Tabella2[[#This Row],[Price]] -> 2000.1 | O22: Media | P22: 461.24125
B23: 10474 | C23: 44876 | D23: Sides & Other | E23: 4.99 | F23: In-store | G23: Credit Card | H23: Pablo Perez | I23: 201 | J23: #VALUE! | K23: {=_FV(Tabella2[[#This Row],[City]],"Paese/area geografica",TRUE)} -> #VALUE! | L23: =Tabella2[[#This Row],[Quantity]]*Tabella2[[#This Row],[Price]] -> 1002.99 | O23: Errore standard | P23: 13.380974
B24: 10475 | C24: 44877 | D24: Burgers | E24: 12.99 | F24: In-store | G24: Credit Card | H24: Pablo Perez | I24: 524 | J24: #VALUE! | K24: {=_FV(Tabella2[[#This Row],[City]],"Paese/area geografica",TRUE)} -> #VALUE! | L24: =Tabella2[[#This Row],[Quantity]]*Tabella2[[#This Row],[Price]] -> 6806.76 | O24: Mediana | P24: 539
B25: 10476 | C25: 44877 | D25: Chicken Sandwiches | E25: 9.95 | F25: In-store | G25: Credit Card | H25: Pablo Perez | I25: 202 | J25: #VALUE! | K25: {=_FV(Tabella2[[#This Row],[City]],"Paese/area geografica",TRUE)} -> #VALUE! | L25: =Tabella2[[#This Row],[Quantity]]*Tabella2[[#This Row],[Price]] -> 2009.9 | O25: Moda | P25: 201
B26: 10477 | C26: 44877 | D26: Fries | E26: 3.49 | F26: In-store | G26: Credit Card | H26: Pablo Perez | I26: 631 | J26: #VALUE! | K26: {=_FV(Tabella2[[#This Row],[City]],"Paese/area geografica",TRUE)} -> #VALUE! | L26: =Tabella2[[#This Row],[Quantity]]*Tabella2[[#This Row],[Price]] -> 2202.19 | O26: Deviazione standard | P26: 214.51334
B27: 10478 | C27: 44877 | D27: Beverages | E27: 2.95 | F27: In-store | G27: Credit Card | H27: Pablo Perez | I27: 678 | J27: #VALUE! | K27: {=_FV(Tabella2[[#This Row],[City]],"Paese/area geografica",TRUE)} -> #VALUE! | L27: =Tabella2[[#This Row],[Quantity]]*Tabella2[[#This Row],[Price]] -> 2000.1 | O27: Varianza campionaria | P27: 46015.973
B28: 10479 | C28: 44877 | D28: Sides & Other | E28: 4.99 | F28: In-store | G28: Credit Card | H28: Pablo Perez | I28: 201 | J28: #VALUE! | K28: {=_FV(Tabella2[[#This Row],[City]],"Paese/area geografica",TRUE)} -> #VALUE! | L28: =Tabella2[[#This Row],[Quantity]]*Tabella2[[#This Row],[Price]] -> 1002.99 | O28: Curtosi | P28: -1.7242037
B29: 10480 | C29: 44878 | D29: Burgers | E29: 12.99 | F29: In-store | G29: Credit Card | H29: Pablo Perez | I29: 509 | J29: #VALUE! | K29: {=_FV(Tabella2[[#This Row],[City]],"Paese/area geografica",TRUE)} -> #VALUE! | L29: =Tabella2[[#This Row],[Quantity]]*Tabella2[[#This Row],[Price]] -> 6611.91 | O29: Asimmetria | P29: -0.2142499
B30: 10481 | C30: 44878 | D30: Chicken Sandwiches | E30: 9.95 | F30: In-store | G30: Credit Card | H30: Pablo Perez | I30: 202 | J30: #VALUE! | K30: {=_FV(Tabella2[[#This Row],[City]],"Paese/area geografica",TRUE)} -> #VALUE! | L30: =Tabella2[[#This Row],[Quantity]]*Tabella2[[#This Row],[Price]] -> 2009.9 | O30: Intervallo | P30: 554
B31: 10482 | C31: 44878 | D31: Fries | E31: 25.5 | F31: In-store | G31: Credit Card | H31: Joao Silva | I31: 631 | J31: #VALUE! | K31: {=_FV(Tabella2[[#This Row],[City]],"Paese/area geografica",TRUE)} -> #VALUE! | L31: =Tabella2[[#This Row],[Quantity]]*Tabella2[[#This Row],[Price]] -> 16090.5 | O31: Minimo | P31: 201
B32: 10483 | C32: 44878 | D32: Beverages | E32: 33.22 | F32: In-store | G32: Credit Card | H32: Joao Silva | I32: 678 | J32: #VALUE! | K32: {=_FV(Tabella2[[#This Row],[City]],"Paese/area geografica",TRUE)} -> #VALUE! | L32: =Tabella2[[#This Row],[Quantity]]*Tabella2[[#This Row],[Price]] -> 22523.16 | O32: Massimo | P32: 755
B33: 10484 | C33: 44878 | D33: Sides & Other | E33: 21.44 | F33: In-store | G33: Credit Card | H33: Joao Silva | I33: 201 | J33: #VALUE! | K33: {=_FV(Tabella2[[#This Row],[City]],"Paese/area geografica",TRUE)} -> #VALUE! | L33: =Tabella2[[#This Row],[Quantity]]*Tabella2[[#This Row],[Price]] -> 4309.44 | O33: Somma | P33: 118539
B34: 10485 | C34: 44879 | D34: Burgers | E34: 27.99 | F34: In-store | G34: Credit Card | H34: Joao Silva | I34: 524 | J34: #VALUE! | K34: {=_FV(Tabella2[[#This Row],[City]],"Paese/area geografica",TRUE)} -> #VALUE! | L34: =Tabella2[[#This Row],[Quantity]]*Tabella2[[#This Row],[Price]] -> 14666.76 | O34: Conteggio | P34: 257
B35: 10486 | C35: 44879 | D35: Chicken Sandwiches | E35: 29.05 | F35: In-store | G35: Credit Card | H35: Joao Silva | I35: 202 | J35: #VALUE! | K35: {=_FV(Tabella2[[#This Row],[City]],"Paese/area geografica",TRUE)} -> #VALUE! | L35: =Tabella2[[#This Row],[Quantity]]*Tabella2[[#This Row],[Price]] -> 5868.1
B36: 10487 | C36: 44879 | D36: Fries | E36: 3.49 | F36: In-store | G36: Credit Card | H36: Joao Silva | I36: 631 | J36: #VALUE! | K36: {=_FV(Tabella2[[#This Row],[City]],"Paese/area geografica",TRUE)} -> #VALUE! | L36: =Tabella2[[#This Row],[Quantity]]*Tabella2[[#This Row],[Price]] -> 2202.19
B37: 10488 | C37: 44879 | D37: Beverages | E37: 2.95 | F37: In-store | G37: Credit Card | H37: Joao Silva | I37: 678 | J37: #VALUE! | K37: {=_FV(Tabella2[[#This Row],[City]],"Paese/area geografica",TRUE)} -> #VALUE! | L37: =Tabella2[[#This Row],[Quantity]]*Tabella2[[#This Row],[Price]] -> 2000.1
B38: 10489 | C38: 44879 | D38: Sides & Other | E38: 4.99 | F38: In-store | G38: Credit Card | H38: Pablo Perez | I38: 201 | J38: #VALUE! | K38: {=_FV(Tabella2[[#This Row],[City]],"Paese/area geografica",TRUE)} -> #VALUE! | L38: =Tabella2[[#This Row],[Quantity]]*Tabella2[[#This Row],[Price]] -> 1002.99 | N38: TOTALE RICAVO | O38: =SUM(Tabella2[Ricavo]) -> 812135.13
B39: 10490 | C39: 44880 | D39: Burgers | E39: 12.99 | F39: In-store | G39: Credit Card | H39: Pablo Perez | I39: 509 | J39: #VALUE! | K39: {=_FV(Tabella2[[#This Row],[City]],"Paese/area geografica",TRUE)} -> #VALUE! | L39: =Tabella2[[#This Row],[Quantity]]*Tabella2[[#This Row],[Price]] -> 6611.91
B40: 10491 | C40: 44880 | D40: Chicken Sandwiches | E40: 9.95 | F40: In-store | G40: Credit Card | H40: Pablo Perez | I40: 202 | J40: #VALUE! | K40: {=_FV(Tabella2[[#This Row],[City]],"Paese/area geografica",TRUE)} -> #VALUE! | L40: =Tabella2[[#This Row],[Quantity]]*Tabella2[[#This Row],[Price]] -> 2009.9
B41: 10492 | C41: 44880 | D41: Fries | E41: 3.49 | F41: In-store | G41: Credit Card | H41: Pablo Perez | I41: 574 | J41: #VALUE! | K41: {=_FV(Tabella2[[#This Row],[City]],"Paese/area geografica",TRUE)} -> #VALUE! | L41: =Tabella2[[#This Row],[Quantity]]*Tabella2[[#This Row],[Price]] -> 2003.26
...

Sheet Clean
B2: Order ID | C2: Date | D2: Product | E2: Price | F2: Quantity | G2: Cost | H2: City | I2: Country | J2: Purchase Type | K2: Payment Method | L2: Manager | M2: Revenue
B3: 10452 | C3: 44872 | D3: Fries | E3: 3.49 | F3: 574 | G3: 0.88 | H3: #VALUE! | I3: {=_FV(H3,"Country/region",TRUE)} -> #VALUE! | J3: Online | K3: Gift Card | L3: Tom Jackson | M3: =Table1[[#This Row],[Price]]*Table1[[#This Row],[Quantity]] -> 2003.26
B4: 10453 | C4: 44872 | D4: Beverages | E4: 2.95 | F4: 746 | G4: 0.47 | H4: #VALUE! | I4: {=_FV(H4,"Country/region",TRUE)} -> #VALUE! | J4: Online | K4: Gift Card | L4: Pablo Perez | M4: =Table1[[#This Row],[Price]]*Table1[[#This Row],[Quantity]] -> 2200.7
B5: 10454 | C5: 44872 | D5: Sides & Other | E5: 4.99 | F5: 201 | G5: 2.25 | H5: #VALUE! | I5: {=_FV(H5,"Country/region",TRUE)} -> #VALUE! | J5: In-store | K5: Gift Card | L5: Joao Silva | M5: =Table1[[#This Row],[Price]]*Table1[[#This Row],[Quantity]] -> 1002.99
B6: 10455 | C6: 44873 | D6: Burgers | E6: 12.99 | F6: 570 | G6: 4.32 | H6: #VALUE! | I6: {=_FV(H6,"Country/region",TRUE)} -> #VALUE! | J6: In-store | K6: Credit Card | L6: Walter Muller | M6: =Table1[[#This Row],[Price]]*Table1[[#This Row],[Quantity]] -> 7404.3
B7: 10456 | C7: 44873 | D7: Chicken Sandwiches | E7: 9.95 | F7: 202 | G7: 2.85 | H7: #VALUE! | I7: {=_FV(H7,"Country/region",TRUE)} -> #VALUE! | J7: In-store | K7: Credit Card | L7: Walter Muller | M7: =Table1[[#This Row],[Price]]*Table1[[#This Row],[Quantity]] -> 2009.9
B8: 10457 | C8: 44873 | D8: Fries | E8: 3.49 | F8: 574 | G8: 0.88 | H8: #VALUE! | I8: {=_FV(H8,"Country/region",TRUE)} -> #VALUE! | J8: In-store | K8: Credit Card | L8: Remy Monet | M8: =Table1[[#This Row],[Price]]*Table1[[#This Row],[Quantity]] -> 2003.26 | O8: Etichette di riga | P8: Somma di Revenue
B9: 10459 | C9: 44873 | D9: Sides & Other | E9: 4.99 | F9: 201 | G9: 2.25 | H9: #VALUE! | I9: {=_FV(H9,"Country/region",TRUE)} -> #VALUE! | J9: In-store | K9: Credit Card | L9: Remy Monet | M9: =Table1[[#This Row],[Price]]*Table1[[#This Row],[Quantity]] -> 1002.99 | O9: #VALUE! | P9: 0.091884728
B10: 10460 | C10: 44874 | D10: Burgers | E10: 12.99 | F10: 555 | G10: 4.32 | H10: #VALUE! | I10: {=_FV(H10,"Country/region",TRUE)} -> #VALUE! | J10: In-store | K10: Credit Card | L10: Walter Muller | M10: =Table1[[#This Row],[Price]]*Table1[[#This Row],[Quantity]] -> 7209.45 | O10: #VALUE! | P10: 0.13324447
B11: 10461 | C11: 44874 | D11: Chicken Sandwiches | E11: 9.95 | F11: 202 | G11: 2.85 | H11: #VALUE! | I11: {=_FV(H11,"Country/region",TRUE)} -> #VALUE! | J11: In-store | K11: Credit Card | L11: Remy Monet | M11: =Table1[[#This Row],[Price]]*Table1[[#This Row],[Quantity]] -> 2009.9 | O11: #VALUE! | P11: 0.34119018
B12: 10462 | C12: 44874 | D12: Fries | E12: 3.49 | F12: 574 | G12: 0.88 | H12: #VALUE! | I12: {=_FV(H12,"Country/region",TRUE)} -> #VALUE! | J12: In-store | K12: Credit Card | L12: Remy Monet | M12: =Table1[[#This Row],[Price]]*Table1[[#This Row],[Quantity]] -> 2003.26 | O12: #VALUE! | P12: 0.1700433
B13: 10463 | C13: 44874 | D13: Beverages | E13: 2.95 | F13: 678 | G13: 0.47 | H13: #VALUE! | I13: {=_FV(H13,"Country/region",TRUE)} -> #VALUE! | J13: In-store | K13: Credit Card | L13: Remy Monet | M13: =Table1[[#This Row],[Price]]*Table1[[#This Row],[Quantity]] -> 2000.1 | O13: #VALUE! | P13: 0.26363731
B14: 10464 | C14: 44874 | D14: Sides & Other | E14: 4.99 | F14: 201 | G14: 2.25 | H14: #VALUE! | I14: {=_FV(H14,"Country/region",TRUE)} -> #VALUE! | J14: In-store | K14: Credit Card | L14: Remy Monet | M14: =Table1[[#This Row],[Price]]*Table1[[#This Row],[Quantity]] -> 1002.99 | O14: Totale complessivo | P14: 1
B15: 10465 | C15: 44875 | D15: Burgers | E15: 12.99 | F15: 555 | G15: 4.32 | H15: #VALUE! | I15: {=_FV(H15,"Country/region",TRUE)} -> #VALUE! | J15: In-store | K15: Credit Card | L15: Pablo Perez | M15: =Table1[[#This Row],[Price]]*Table1[[#This Row],[Quantity]] -> 7209.45
B16: 10466 | C16: 44875 | D16: Chicken Sandwiches | E16: 9.95 | F16: 202 | G16: 2.85 | H16: #VALUE! | I16: {=_FV(H16,"Country/region",TRUE)} -> #VALUE! | J16: In-store | K16: Credit Card | L16: Pablo Perez | M16: =Table1[[#This Row],[Price]]*Table1[[#This Row],[Quantity]] -> 2009.9
B17: 10467 | C17: 44875 | D17: Fries | E17: 3.49 | F17: 574 | G17: 0.88 | H17: #VALUE! | I17: {=_FV(H17,"Country/region",TRUE)} -> #VALUE! | J17: In-store | K17: Credit Card | L17: Pablo Perez | M17: =Table1[[#This Row],[Price]]*Table1[[#This Row],[Quantity]] -> 2003.26
B18: 10468 | C18: 44875 | D18: Beverages | E18: 2.95 | F18: 678 | G18: 0.47 | H18: #VALUE! | I18: {=_FV(H18,"Country/region",TRUE)} -> #VALUE! | J18: In-store | K18: Credit Card | L18: Pablo Perez | M18: =Table1[[#This Row],[Price]]*Table1[[#This Row],[Quantity]] -> 2000.1
B19: 10470 | C19: 44876 | D19: Burgers | E19: 12.99 | F19: 555 | G19: 4.32 | H19: #VALUE! | I19: {=_FV(H19,"Country/region",TRUE)} -> #VALUE! | J19: In-store | K19: Credit Card | L19: Pablo Perez | M19: =Table1[[#This Row],[Price]]*Table1[[#This Row],[Quantity]] -> 7209.45
B20: 10471 | C20: 44876 | D20: Chicken Sandwiches | E20: 9.95 | F20: 202 | G20: 2.85 | H20: #VALUE! | I20: {=_FV(H20,"Country/region",TRUE)} -> #VALUE! | J20: In-store | K20: Credit Card | L20: Pablo Perez | M20: =Table1[[#This Row],[Price]]*Table1[[#This Row],[Quantity]] -> 2009.9
B21: 10472 | C21: 44876 | D21: Fries | E21: 3.49 | F21: 631 | G21: 0.88 | H21: #VALUE! | I21: {=_FV(H21,"Country/region",TRUE)} -> #VALUE! | J21: In-store | K21: Credit Card | L21: Pablo Perez | M21: =Table1[[#This Row],[Price]]*Table1[[#This Row],[Quantity]] -> 2202.19
B22: 10473 | C22: 44876 | D22: Beverages | E22: 2.95 | F22: 678 | G22: 0.47 | H22: #VALUE! | I22: {=_FV(H22,"Country/region",TRUE)} -> #VALUE! | J22: In-store | K22: Credit Card | L22: Pablo Perez | M22: =Table1[[#This Row],[Price]]*Table1[[#This Row],[Quantity]] -> 2000.1
B23: 10474 | C23: 44876 | D23: Sides & Other | E23: 4.99 | F23: 201 | G23: 2.25 | H23: #VALUE! | I23: {=_FV(H23,"Country/region",TRUE)} -> #VALUE! | J23: In-store | K23: Credit Card | L23: Pablo Perez | M23: =Table1[[#This Row],[Price]]*Table1[[#This Row],[Quantity]] -> 1002.99
B24: 10475 | C24: 44877 | D24: Burgers | E24: 12.99 | F24: 524 | G24: 4.32 | H24: #VALUE! | I24: {=_FV(H24,"Country/region",TRUE)} -> #VALUE! | J24: In-store | K24: Credit Card | L24: Pablo Perez | M24: =Table1[[#This Row],[Price]]*Table1[[#This Row],[Quantity]] -> 6806.76
B25: 10476 | C25: 44877 | D25: Chicken Sandwiches | E25: 9.95 | F25: 202 | G25: 2.85 | H25: #VALUE! | I25: {=_FV(H25,"Country/region",TRUE)} -> #VALUE! | J25: In-store | K25: Credit Card | L25: Pablo Perez | M25: =Table1[[#This Row],[Price]]*Table1[[#This Row],[Quantity]] -> 2009.9
B26: 10477 | C26: 44877 | D26: Fries | E26: 3.49 | F26: 631 | G26: 0.88 | H26: #VALUE! | I26: {=_FV(H26,"Country/region",TRUE)} -> #VALUE! | J26: In-store | K26: Credit Card | L26: Pablo Perez | M26: =Table1[[#This Row],[Price]]*Table1[[#This Row],[Quantity]] -> 2202.19
... B256: 10713 | C256: 44924 | D256: Beverages | E256: 2.95 | F256: 678 | G256: 0.47 | H256: #VALUE! | I256: {=_FV(H256,"Country/region",TRUE)} -> #VALUE! | J256: Drive-thru | K256: Gift Card | L256: Walter Muller | M256: =Table1[[#This Row],[Price]]*Table1[[#This Row],[Quantity]] -> 2000.1

Sheet Analysis
B2: Data Analysis Questions
B4: 1) What is our best selling product?
B6: 2) What is our total revenue?
B8: 3) What is the revenue breakdown by payment method?
D13: Ricavo | E13: Quantity2 | H13: Quantity2
C14: Formula1 | G14: Beverages | H14: 35666
C15: Beverages | G15: Fries | H15: 32067
C16: Burgers | G16: Burgers | H16: 29572
C17: Chicken Sandwiches | G17: Chicken Sandwiches | H17: 11184
C18: Fries | G18: Sides & Other | H18: 10050
C19: Sides & Other | G19: Totale complessivo | H19: 118539
C20: Joao Silva | D20: 283555.36 | E20: 37196
C21: Beverages | D21: 56129.56 | E21: 12070
C22: Burgers | D22: 123561.93 | E22: 8907 | H22: Somma di Ricavo
C23: Chicken Sandwiches | D23: 36792.7 | E23: 3310 | G23: Credit Card | H23: 0.49722372
C24: Fries | D24: 47716.88 | E24: 9693 | G24: Cash | H24: 0.29489446
C25: Sides & Other | D25: 19354.29 | E25: 3216 | G25: Gift Card | H25: 0.20788182
C26: Pablo Perez | D26: 136430.04 | E26: 20472 | G26: Totale complessivo | H26: 1
C27: Beverages | D27: 18402.1 | E27: 6238
C28: Burgers | D28: 73692.27 | E28: 5673
C29: Chicken Sandwiches | D29: 18089.1 | E29: 1818
C30: Fries | D30: 17219.66 | E30: 4934
C31: Sides & Other | D31: 9026.91 | E31: 1809
C32: Remy Monet | D32: 79927.9 | E32: 12508
C33: Beverages | D33: 10401.7 | E33: 3526
C34: Burgers | D34: 39437.64 | E34: 3036
C35: Chicken Sandwiches | D35: 12059.4 | E35: 1212
C36: Fries | D36: 13014.21 | E36: 3729
C37: Sides & Other | D37: 5014.95 | E37: 1005
C38: Tom Jackson | D38: 211522.88 | E38: 33578
... C50: Totale complessivo | D50: 812135.13 | E50: 118539

Sheet Findings
B2: Select Manager -> | C2: Tom Jackson | J2: Tom Jackson
J3: Pablo Perez
B4: Geography | J4: Joao Silva
B5: Country | C5: =_xlfn.XLOOKUP(C2,Table1[Manager],Table1[Country]) -> #VALUE! | J5: Walter Muller
B6: City | C6: =_xlfn.XLOOKUP(C2,Table1[Manager],Table1[City]) -> #VALUE! | J6: Remy Monet
B8: Revenue
B9: Fries | C9: =SUMIFS(Table1[Revenue],Table1[Product],Findings!B9,Table1[Manager],Findings!$C$2) -> 34638.25
B10: Beverages | C10: =SUMIFS(Table1[Revenue],Table1[Product],Findings!B10,Table1[Manager],Findings!$C$2) -> 28803.8
B11: Sides & Other | C11: =SUMIFS(Table1[Revenue],Table1[Product],Findings!B11,Table1[Manager],Findings!$C$2) -> 14041.86
B12: Burgers | C12: =SUMIFS(Table1[Revenue],Table1[Product],Findings!B12,Table1[Manager],Findings!$C$2) -> 101880.57
B13: Chicken Sandwiches | C13: =SUMIFS(Table1[Revenue],Table1[Product],Findings!B13,Table1[Manager],Findings!$C$2) -> 32158.4
B14: Total | C14: =SUM(C9:C13) -> 211522.88
